<mujoco model="marathon_002">
  <compiler angle="radian" meshdir="meshes" autolimits="true"/>

  <asset>
    <texture type="skybox" builtin="gradient" rgb1=".3 .5 .7" rgb2="0 0 0" width="32" height="512"/>
    <texture name="body" type="cube" builtin="flat" mark="cross" width="128" height="128"
      rgb1="0.8 0.6 0.4" rgb2="0.8 0.6 0.4" markrgb="1 1 1" random="0.01"/>
    <material name="body" texture="body" texuniform="true" rgba="0.8 0.6 .4 1"/>
    <texture name="grid" type="2d" builtin="checker" width="512" height="512"
      rgb1=".1 .2 .3" rgb2=".2 .3 .4"/>
    <material name="grid" texture="grid" texrepeat="1 1" texuniform="true" reflectance=".2"/>
    <mesh name="base_link" file="base_link.STL"/>
    <mesh name="right_shoulder_pitch_link" file="right_shoulder_pitch_link.STL"/>
    <mesh name="right_shoulder_roll_link" file="right_shoulder_roll_link.STL"/>
    <mesh name="right_elbow_pitch_link" file="right_elbow_pitch_link.STL"/>
    <mesh name="left_shoulder_pitch_link" file="left_shoulder_pitch_link.STL"/>
    <mesh name="left_shoulder_roll_link" file="left_shoulder_roll_link.STL"/>
    <mesh name="left_elbow_pitch_link" file="left_elbow_pitch_link.STL"/>
    <mesh name="right_leg_pelvic_pitch_link" file="right_leg_pelvic_pitch_link.STL"/>
    <mesh name="right_leg_pelvic_roll_link" file="right_leg_pelvic_roll_link.STL"/>
    <mesh name="right_leg_pelvic_yaw_link" file="right_leg_pelvic_yaw_link.STL"/>
    <mesh name="right_leg_knee_pitch_link" file="right_leg_knee_pitch_link.STL"/>
    <mesh name="right_leg_ankle_pitch_link" file="right_leg_ankle_pitch_link.STL"/>
    <mesh name="right_leg_ankle_roll_link" file="right_leg_ankle_roll_link.STL"/>
    <mesh name="left_leg_pelvic_pitch_link" file="left_leg_pelvic_pitch_link.STL"/>
    <mesh name="left_leg_pelvic_roll_link" file="left_leg_pelvic_roll_link.STL"/>
    <mesh name="left_leg_pelvic_yaw_link" file="left_leg_pelvic_yaw_link.STL"/>
    <mesh name="left_leg_knee_pitch_link" file="left_leg_knee_pitch_link.STL"/>
    <mesh name="left_leg_ankle_pitch_link" file="left_leg_ankle_pitch_link.STL"/>
    <mesh name="left_leg_ankle_roll_link" file="left_leg_ankle_roll_link.STL"/>
  </asset>

  <worldbody>
    <geom name="ground" type="plane" pos="0 0 0" size="10 10 0.1" material="grid" condim="3"/>
    <light name="main_light" pos="0 -3 5" dir="0 1 -1" diffuse="1 1 1" specular="0.5 0.5 0.5" directional="true" castshadow="true"/>
    
    <body name="base_link" pos="0 0 0.868">
      <inertial pos="-0.0004287 -1.711E-05 0.23553" fullinertia="0.53359 0.5071 0.094812 -3.862e-05 0.0045012 -0.00015184" mass="15.517"/>
      <freejoint name="base_link"/>
      <geom type="mesh" mesh="base_link" rgba="1 1 1 1"/>

      <!-- ====================== 新增：固定腰部（定位专用，无运动） ====================== -->
      <body name="waist_fixed_link" pos="0 0 -0.15">
        <!-- 无关节 = 固定于父连杆 -->
        <geom type="cylinder" size="0.06 0.02" rgba="0.9 0.9 0.9 1"/> <!-- 小型腰柱 -->
      </body>
      <!-- ============================================================================ -->

      <!-- 右侧手臂 -->
      <body name="right_shoulder_pitch_link" pos="0 -0.144 0.4793">
        <inertial pos="0.0030286 -0.052083 8.95E-05" fullinertia="0.00039239 0.00038548 0.00050373 1.626e-05 8.3e-07 -2.33e-06" mass="0.66099"/>
        <joint name="right_shoulder_pitch_joint" axis="0 1 0" range="-3.1416 1.0472"/>
        <geom type="mesh" mesh="right_shoulder_pitch_link" rgba="1 1 1 1"/>
        <body name="right_shoulder_roll_link" pos="0 -0.058 0">
          <inertial pos="-0.0023626 -0.0043411 -0.097936" fullinertia="0.0013023 0.0013747 0.00031857 3.33e-06 4.42e-05 -0.00012187" mass="0.32487"/>
          <joint name="right_shoulder_roll_joint" axis="1 0 0" range="-3.1416 0.3491"/>
          <geom type="mesh" mesh="right_shoulder_roll_link" rgba="1 1 1 1"/>
          <body name="right_elbow_pitch_link" pos="0 0 -0.2015">
            <inertial pos="0.00062979 -0.00255 -0.014614" fullinertia="0.0011842 0.001121 0.00030511 1.214e-05 -4.8e-06 6.56e-06" mass="0.63926"/>
            <joint name="right_elbow_pitch_joint" axis="0 1 0" range="-1.8675 0.0"/>
            <geom type="mesh" mesh="right_elbow_pitch_link" rgba="1 1 1 1"/>
            
            <!-- ====================== 新增：右手迷你手腕 ====================== -->
            <body name="right_wrist_link" pos="0 0 -0.03">
              <joint name="right_wrist_roll_joint" axis="1 0 0" range="-1.57 1.57"/>
              <inertial pos="0 0 0" mass="0.02" diaginertia="1e-5 1e-5 1e-5"/>
              <geom type="cylinder" size="0.02 0.015" rgba="0.8 0.8 0.8 1"/>
            </body>
            <!-- ============================================================== -->
          </body>
        </body>
      </body>

      <!-- 左侧手臂 -->
      <body name="left_shoulder_pitch_link" pos="0 0.144 0.4793">
        <inertial pos="0.003024 0.052268 0.0001184" fullinertia="0.00038606 0.00038514 0.00049747 -1.6e-05 1.2e-06 3.27e-06" mass="0.65764"/>
        <joint name="left_shoulder_pitch_joint" axis="0 1 0" range="-3.1416 1.0472"/>
        <geom type="mesh" mesh="left_shoulder_pitch_link" rgba="1 1 1 1"/>
        <body name="left_shoulder_roll_link" pos="0 0.058 0">
          <inertial pos="-0.0012088 0.0047034 -0.098785" fullinertia="0.0013282 0.0013979 0.00032539 -1.79e-06 5.01e-05 0.000132" mass="0.32724"/>
          <joint name="left_shoulder_roll_joint" axis="1 0 0" range="-0.3491 3.1416"/>
          <geom type="mesh" mesh="left_shoulder_roll_link" rgba="1 0.8 0.8 1"/>
          <body name="left_elbow_pitch_link" pos="0 0 -0.2015">
            <inertial pos="-0.00062979 0.0025546 -0.014614" fullinertia="0.0011842 0.001121 0.00030511 1.214e-05 4.8e-06 -6.56e-06" mass="0.63926"/>
            <joint name="left_elbow_pitch_joint" axis="0 1 0" range="-1.8675 0.0"/>
            <geom type="mesh" mesh="left_elbow_pitch_link" rgba="1 1 1 1"/>
            
            <!-- ====================== 新增：左手迷你手腕 ====================== -->
            <body name="left_wrist_link" pos="0 0 -0.03">
              <joint name="left_wrist_roll_joint" axis="1 0 0" range="-1.57 1.57"/>
              <inertial pos="0 0 0" mass="0.02" diaginertia="1e-5 1e-5 1e-5"/>
              <geom type="cylinder" size="0.02 0.015" rgba="0.8 0.8 0.8 1"/>
            </body>
            <!-- ============================================================== -->
          </body>
        </body>
      </body>

      <!-- 腿部结构（完全保留原样） -->
      <body name="right_leg_pelvic_pitch_link" pos="0 -0.07 0.0815">
        <inertial pos="0.060873 -0.069043 -0.04845" fullinertia="0.0068292 0.0054898 0.0054615 0.000881 0.000808 -0.00082575" mass="2.8001"/>
        <joint name="right_leg_pelvic_pitch_joint" axis="0 1 0" range="-1.9199 1.5708"/>
        <geom type="mesh" mesh="right_leg_pelvic_pitch_link" rgba="1 1 1 1"/>
        <body name="right_leg_pelvic_roll_link" pos="0 -0.0755 -0.055">
          <inertial pos="0.034819 5.191E-05 -0.052217" fullinertia="0.0014584 0.0015459 0.00058466 -8.2e-07 -0.0003896 4.99e-06" mass="0.62862"/>
          <joint name="right_leg_pelvic_roll_joint" axis="1 0 0" range="-1.5708 0.17453"/>
          <geom type="mesh" mesh="right_leg_pelvic_roll_link" rgba="1 1 1 1"/>
          <body name="right_leg_pelvic_yaw_link" pos="0.007 0 -0.0975">
            <inertial pos="-0.0097934 0.0071978 -0.18611" fullinertia="0.060072 0.061644 0.0069952 0.00043717 -0.0039166 0.0028566" mass="4.1607"/>
            <joint name="right_leg_pelvic_yaw_joint" axis="0 0 1" range="-1.5708 1.5708"/>
            <geom type="mesh" mesh="right_leg_pelvic_yaw_link" rgba="1 1 1 1"/>
            <body name="right_leg_knee_pitch_link" pos="-0.02 0 -0.2775">
              <inertial pos="0.0038038 -0.0031714 -0.19146" fullinertia="0.038303 0.038375 0.0034575 -5.015e-05 -0.00084807 0.0016444" mass="3.2321"/>
              <joint name="right_leg_knee_pitch_joint" axis="0 1 0" range="0.0 2.5307"/>
              <geom type="mesh" mesh="right_leg_knee_pitch_link" rgba="1 1 1 1"/>
              <body name="right_leg_ankle_pitch_link" pos="0 0 -0.453">
                <inertial pos="0 0 0" fullinertia="3.31e-05 1.097e-05 3.21e-05 0.0 0.0 0.0" mass="0.11165"/>
                <joint name="right_leg_ankle_pitch_joint" axis="0 1 0" range="-0.87266 0.50614"/>
                <geom type="mesh" mesh="right_leg_ankle_pitch_link" rgba="1 1 1 1"/>
                <body name="right_leg_ankle_roll_link" pos="0 0 0">
                  <inertial pos="0.01896 3.72E-06 -0.040477" fullinertia="0.0013195 0.0054632 0.0059201 0.0 0.000232 1e-08" mass="1.0156"/>
                  <joint name="right_leg_ankle_roll_joint" axis="1 0 0" range="-0.50614 0.50614"/>
                  <geom type="mesh" mesh="right_leg_ankle_roll_link" rgba="1 1 1 1"/>
                </body>
              </body>
            </body>
          </body>
        </body>
      </body>
      <body name="left_leg_pelvic_pitch_link" pos="0 0.07 0.0815">
        <inertial pos="0.060908 0.069029 -0.048507" fullinertia="0.0068205 0.0054779 0.0054584 -0.00087312 0.000805 0.00082912" mass="2.7971"/>
        <joint name="left_leg_pelvic_pitch_joint" axis="0 1 0" range="-1.9199 1.5708"/>
        <geom type="mesh" mesh="left_leg_pelvic_pitch_link" rgba="1 1 1 1"/>
        <body name="left_leg_pelvic_roll_link" pos="0 0.0755 -0.055">
          <inertial pos="0.03481922 5.191E-05 -0.05221705" fullinertia="0.00145838 0.00154585 0.00058466 -8.2e-07 -0.0003896 4.99e-06" mass="0.62861886"/>
          <joint name="left_leg_pelvic_roll_joint" axis="1 0 0" range="-0.17453 1.5708"/>
          <geom type="mesh" mesh="left_leg_pelvic_roll_link" rgba="1 1 1 1"/>
          <body name="left_leg_pelvic_yaw_link" pos="0.007 0 -0.0975">
            <inertial pos="-0.00979341 -0.00720895 -0.18611002" fullinertia="0.06005604 0.06164362 0.00700986 -0.000431 -0.00391069 -0.00284451" mass="4.16066501"/>
            <joint name="left_leg_pelvic_yaw_joint" axis="0 0 1" range="-1.5708 1.5708"/>
            <geom type="mesh" mesh="left_leg_pelvic_yaw_link" rgba="1 1 1 1"/>
            <body name="left_leg_knee_pitch_link" pos="-0.02 0 -0.2775">
              <inertial pos="0.00381328 0.00304906 -0.19321143" fullinertia="0.03812876 0.03818465 0.00346024 5.48e-05 -0.00091437 -0.00158824" mass="3.21814013"/>
              <joint name="left_leg_knee_pitch_joint" axis="0 1 0" range="0.0 2.5307"/>
              <geom type="mesh" mesh="left_leg_knee_pitch_link" rgba="1 1 1 1"/>
              <body name="left_leg_ankle_pitch_link" pos="0 -0.0002 -0.453">
                <inertial pos="0 0 0" fullinertia="3.31e-05 1.097e-05 3.21e-05 0.0 0.0 0.0" mass="0.11165331"/>
                <joint name="left_leg_ankle_pitch_joint" axis="0 1 0" range="-0.87266 0.50614"/>
                <geom type="mesh" mesh="left_leg_ankle_pitch_link" rgba="1 1 1 1"/>
                <body name="left_leg_ankle_roll_link" pos="0 0 0">
                  <inertial pos="0.01896557 3.72E-06 -0.04048111" fullinertia="0.00131954 0.00546321 0.00592016 0.0 0.000232 1e-08" mass="1.01655827"/>
                  <joint name="left_leg_ankle_roll_joint" axis="1 0 0" range="-0.50614 0.50614"/>
                  <geom type="mesh" mesh="left_leg_ankle_roll_link" rgba="1 1 1 1"/>
                </body>
              </body>
            </body>
          </body>
        </body>
      </body>
    </body>
  </worldbody>

  <actuator>
    <!-- 原有电机（完全保留） -->
    <motor name="right_shoulder_pitch_joint" joint="right_shoulder_pitch_joint"/>
    <motor name="right_shoulder_roll_joint" joint="right_shoulder_roll_joint"/>
    <motor name="right_elbow_pitch_joint" joint="right_elbow_pitch_joint"/>
    <motor name="left_shoulder_pitch_joint" joint="left_shoulder_pitch_joint"/>
    <motor name="left_shoulder_roll_joint" joint="left_shoulder_roll_joint"/>
    <motor name="left_elbow_pitch_joint" joint="left_elbow_pitch_joint"/>
    <motor name="right_leg_pelvic_pitch_joint" joint="right_leg_pelvic_pitch_joint"/>
    <motor name="right_leg_pelvic_roll_joint" joint="right_leg_pelvic_roll_joint"/>
    <motor name="right_leg_pelvic_yaw_joint" joint="right_leg_pelvic_yaw_joint"/>
    <motor name="right_leg_knee_pitch_joint" joint="right_leg_knee_pitch_joint"/>
    <motor name="right_leg_ankle_pitch_joint" joint="right_leg_ankle_pitch_joint"/>
    <motor name="right_leg_ankle_roll_joint" joint="right_leg_ankle_roll_joint"/>
    <motor name="left_leg_pelvic_pitch_joint" joint="left_leg_pelvic_pitch_joint"/>
    <motor name="left_leg_pelvic_roll_joint" joint="left_leg_pelvic_roll_joint"/>
    <motor name="left_leg_pelvic_yaw_joint" joint="left_leg_pelvic_yaw_joint"/>
    <motor name="left_leg_knee_pitch_joint" joint="left_leg_knee_pitch_joint"/>
    <motor name="left_leg_ankle_pitch_joint" joint="left_leg_ankle_pitch_joint"/>
    <motor name="left_leg_ankle_roll_joint" joint="left_leg_ankle_roll_joint"/>
    
    <!-- ====================== 新增：手腕电机 ====================== -->
    <motor name="right_wrist_roll_joint" joint="right_wrist_roll_joint"/>
    <motor name="left_wrist_roll_joint" joint="left_wrist_roll_joint"/>
    <!-- =========================================================== -->
  </actuator>
</mujoco>
