<?xml version="1.0" encoding="utf-8"?>
<robot
  name="CB02_URDF_ECS_WK_0904B">
  <mujoco>
  <compiler meshdir="../meshes" />
  </mujoco>
  <link
    name="base_link">
    <inertial>
      <origin
        xyz="0.00090049 3.158E-05 0.059413"
        rpy="0 0 0" />
      <mass
        value="4.478" />
      <inertia
        ixx="0.013418"
        ixy="4.84E-06"
        ixz="-4E-07"
        iyy="0.0086488"
        iyz="-1.104E-05"
        izz="0.011258" />
    </inertial>
    <visual>
      <origin
        xyz="0 0 0"
        rpy="0 0 0" />
      <geometry>
        <mesh
          filename="../meshes/base_link.STL" />
      </geometry>
      <material
        name="">
        <color
          rgba="0.79216 0.81961 0.93333 1" />
      </material>
    </visual>
    <collision>
      <origin
        xyz="0 0 0"
        rpy="0 0 0" />
      <geometry>
        <mesh
          filename="../meshes/base_link.STL" />
      </geometry>
    </collision>
  </link>
  <link
    name="left_leg_pelvic_pitch_link">
    <inertial>
      <origin
        xyz="0.007392 0.07357868 -0.04762245"
        rpy="0 0 0" />
      <mass
        value="2.16712093" />
      <inertia
        ixx="0.0038978"
        ixy="-2.998E-05"
        ixz="8.411E-05"
        iyy="0.0025035"
        iyz="-0.00071248"
        izz="0.00266976" />
    </inertial>
    <visual>
      <origin
        xyz="0 0 0"
        rpy="0 0 0" />
      <geometry>
        <mesh
          filename="../meshes/left_leg_pelvic_pitch_link.STL" />
      </geometry>
      <material
        name="">
        <color
          rgba="0.792156862745098 0.819607843137255 0.933333333333333 1" />
      </material>
    </visual>
    <collision>
      <origin
        xyz="0 0 0"
        rpy="0 0 0" />
      <geometry>
        <mesh
          filename="../meshes/left_leg_pelvic_pitch_link.STL" />
      </geometry>
    </collision>
  </link>
  <joint
    name="left_leg_pelvic_pitch_joint"
    type="revolute">
    <origin
      xyz="0 0.061 0.0575"
      rpy="0 0 0" />
    <parent
      link="base_link" />
    <child
      link="left_leg_pelvic_pitch_link" />
    <axis
      xyz="0 1 0" />
    <limit
      lower="-1.9199"
      upper="1.5708"
      effort="0"
      velocity="0" />
  </joint>
  <link
    name="left_leg_pelvic_roll_link">
    <inertial>
      <origin
        xyz="0.03179766 1.95E-05 -0.04775155"
        rpy="0 0 0" />
      <mass
        value="0.49485227" />
      <inertia
        ixx="0.00108111"
        ixy="2.8E-07"
        ixz="0.00023852"
        iyy="0.00109255"
        iyz="-5.74E-06"
        izz="0.00044936" />
    </inertial>
    <visual>
      <origin
        xyz="0 0 0"
        rpy="0 0 0" />
      <geometry>
        <mesh
          filename="../meshes/left_leg_pelvic_roll_link.STL" />
      </geometry>
      <material
        name="">
        <color
          rgba="0.792156862745098 0.819607843137255 0.933333333333333 1" />
      </material>
    </visual>
    <collision>
      <origin
        xyz="0 0 0"
        rpy="0 0 0" />
      <geometry>
        <mesh
          filename="../meshes/left_leg_pelvic_roll_link.STL" />
      </geometry>
    </collision>
  </link>
  <joint
    name="left_leg_pelvic_roll_joint"
    type="revolute">
    <origin
      xyz="-0.0028 0.0815 -0.055"
      rpy="0 0 0" />
    <parent
      link="left_leg_pelvic_pitch_link" />
    <child
      link="left_leg_pelvic_roll_link" />
    <axis
      xyz="1 0 0" />
    <limit
      lower="-0.17453"
      upper="1.5708"
      effort="0"
      velocity="0" />
  </joint>
  <link
    name="left_leg_pelvic_yaw_link">
    <inertial>
      <origin
        xyz="-0.00776171 0.00252331 -0.16639404"
        rpy="0 0 0" />
      <mass
        value="3.6735854" />
      <inertia
        ixx="0.05377406"
        ixy="-0.00022287"
        ixz="0.00357725"
        iyy="0.05489217"
        iyz="-0.00098325"
        izz="0.00463387" />
    </inertial>
    <visual>
      <origin
        xyz="0 0 0"
        rpy="0 0 0" />
      <geometry>
        <mesh
          filename="../meshes/left_leg_pelvic_yaw_link.STL" />
      </geometry>
      <material
        name="">
        <color
          rgba="0.792156862745098 0.819607843137255 0.933333333333333 1" />
      </material>
    </visual>
    <collision>
      <origin
        xyz="0 0 0"
        rpy="0 0 0" />
      <geometry>
        <mesh
          filename="../meshes/left_leg_pelvic_yaw_link.STL" />
      </geometry>
    </collision>
  </link>
  <joint
    name="left_leg_pelvic_yaw_joint"
    type="revolute">
    <origin
      xyz="0 0 -0.0975"
      rpy="0 0 0" />
    <parent
      link="left_leg_pelvic_roll_link" />
    <child
      link="left_leg_pelvic_yaw_link" />
    <axis
      xyz="0 0 1" />
    <limit
      lower="-1.5708"
      upper="1.5708"
      effort="0"
      velocity="0" />
  </joint>
  <link
    name="left_leg_knee_pitch_link">
    <inertial>
      <origin
        xyz="0.00342465 -0.00267008 -0.19670471"
        rpy="0 0 0" />
      <mass
        value="3.70154182" />
      <inertia
        ixx="0.04242281"
        ixy="5.79E-05"
        ixz="0.00173533"
        iyy="0.04255239"
        iyz="-0.00152305"
        izz="0.00396465" />
    </inertial>
    <visual>
      <origin
        xyz="0 0 0"
        rpy="0 0 0" />
      <geometry>
        <mesh
          filename="../meshes/left_leg_knee_pitch_link.STL" />
      </geometry>
      <material
        name="">
        <color
          rgba="0.792156862745098 0.819607843137255 0.933333333333333 1" />
      </material>
    </visual>
    <collision>
      <origin
        xyz="0 0 0"
        rpy="0 0 0" />
      <geometry>
        <mesh
          filename="../meshes/left_leg_knee_pitch_link.STL" />
      </geometry>
    </collision>
  </link>
  <joint
    name="left_leg_knee_pitch_joint"
    type="revolute">
    <origin
      xyz="-0.02 0 -0.2735"
      rpy="0 0 0" />
    <parent
      link="left_leg_pelvic_yaw_link" />
    <child
      link="left_leg_knee_pitch_link" />
    <axis
      xyz="0 1 0" />
    <limit
      lower="0"
      upper="2.5307"
      effort="0"
      velocity="0" />
  </joint>
  <link
    name="left_leg_ankle_pitch_link">
    <inertial>
      <origin
        xyz="0 -1.93E-06 0"
        rpy="0 0 0" />
      <mass
        value="0.05737571" />
      <inertia
        ixx="1.172E-05"
        ixy="0"
        ixz="0"
        iyy="9.47E-06"
        iyz="0"
        izz="1.044E-05" />
    </inertial>
    <visual>
      <origin
        xyz="0 0 0"
        rpy="0 0 0" />
      <geometry>
        <mesh
          filename="../meshes/left_leg_ankle_pitch_link.STL" />
      </geometry>
      <material
        name="">
        <color
          rgba="0.792156862745098 0.819607843137255 0.933333333333333 1" />
      </material>
    </visual>
    <collision>
      <origin
        xyz="0 0 0"
        rpy="0 0 0" />
      <geometry>
        <mesh
          filename="../meshes/left_leg_ankle_pitch_link.STL" />
      </geometry>
    </collision>
  </link>
  <joint
    name="left_leg_ankle_pitch_joint"
    type="revolute">
    <origin
      xyz="0 0 -0.453"
      rpy="0 0 0" />
    <parent
      link="left_leg_knee_pitch_link" />
    <child
      link="left_leg_ankle_pitch_link" />
    <axis
      xyz="0 1 0" />
    <limit
      lower="-0.87266"
      upper="0.50614"
      effort="0"
      velocity="0" />
  </joint>
  <link
    name="left_leg_ankle_roll_link">
    <inertial>
      <origin
        xyz="0.01874436 0.00117256 -0.04094853"
        rpy="0 0 0" />
      <mass
        value="0.88258515" />
      <inertia
        ixx="0.00105616"
        ixy="9.17E-05"
        ixz="-0.00035707"
        iyy="0.00422731"
        iyz="-1.272E-05"
        izz="0.00447916" />
    </inertial>
    <visual>
      <origin
        xyz="0 0 0"
        rpy="0 0 0" />
      <geometry>
        <mesh
          filename="../meshes/left_leg_ankle_roll_link.STL" />
      </geometry>
      <material
        name="">
        <color
          rgba="0.792156862745098 0.819607843137255 0.933333333333333 1" />
      </material>
    </visual>
    <collision>
      <origin
        xyz="0 0 0"
        rpy="0 0 0" />
      <geometry>
        <mesh
          filename="../meshes/left_leg_ankle_roll_link.STL" />
      </geometry>
    </collision>
  </link>
  <joint
    name="left_leg_ankle_roll_joint"
    type="revolute">
    <origin
      xyz="0 0 0"
      rpy="0 0 0" />
    <parent
      link="left_leg_ankle_pitch_link" />
    <child
      link="left_leg_ankle_roll_link" />
    <axis
      xyz="1 0 0" />
    <limit
      lower="-0.50614"
      upper="0.50614"
      effort="0"
      velocity="0" />
  </joint>
  <link
    name="right_leg_pelvic_pitch_link">
    <inertial>
      <origin
        xyz="0.00736841 -0.07351545 -0.04756625"
        rpy="0 0 0" />
      <mass
        value="2.16919842" />
      <inertia
        ixx="0.00391559"
        ixy="2.66E-05"
        ixz="8.106E-05"
        iyy="0.00251332"
        iyz="0.00072134"
        izz="0.00268025" />
    </inertial>
    <visual>
      <origin
        xyz="0 0 0"
        rpy="0 0 0" />
      <geometry>
        <mesh
          filename="../meshes/right_leg_pelvic_pitch_link.STL" />
      </geometry>
      <material
        name="">
        <color
          rgba="0.792156862745098 0.819607843137255 0.933333333333333 1" />
      </material>
    </visual>
    <collision>
      <origin
        xyz="0 0 0"
        rpy="0 0 0" />
      <geometry>
        <mesh
          filename="../meshes/right_leg_pelvic_pitch_link.STL" />
      </geometry>
    </collision>
  </link>
  <joint
    name="right_leg_pelvic_pitch_joint"
    type="revolute">
    <origin
      xyz="0 -0.061 0.0575"
      rpy="0 0 0" />
    <parent
      link="base_link" />
    <child
      link="right_leg_pelvic_pitch_link" />
    <axis
      xyz="0 1 0" />
    <limit
      lower="-1.9199"
      upper="1.5708"
      effort="0"
      velocity="0" />
  </joint>
  <link
    name="right_leg_pelvic_roll_link">
    <inertial>
      <origin
        xyz="0.03179766 1.95E-05 -0.04775155"
        rpy="0 0 0" />
      <mass
        value="0.49485227" />
      <inertia
        ixx="0.00108111"
        ixy="2.8E-07"
        ixz="0.00023852"
        iyy="0.00109255"
        iyz="-5.74E-06"
        izz="0.00044936" />
    </inertial>
    <visual>
      <origin
        xyz="0 0 0"
        rpy="0 0 0" />
      <geometry>
        <mesh
          filename="../meshes/right_leg_pelvic_roll_link.STL" />
      </geometry>
      <material
        name="">
        <color
          rgba="0.792156862745098 0.819607843137255 0.933333333333333 1" />
      </material>
    </visual>
    <collision>
      <origin
        xyz="0 0 0"
        rpy="0 0 0" />
      <geometry>
        <mesh
          filename="../meshes/right_leg_pelvic_roll_link.STL" />
      </geometry>
    </collision>
  </link>
  <joint
    name="right_leg_pelvic_roll_joint"
    type="revolute">
    <origin
      xyz="-0.0028 -0.0815 -0.055"
      rpy="0 0 0" />
    <parent
      link="right_leg_pelvic_pitch_link" />
    <child
      link="right_leg_pelvic_roll_link" />
    <axis
      xyz="1 0 0" />
    <limit
      lower="-1.5708"
      upper="0.17453"
      effort="0"
      velocity="0" />
  </joint>
  <link
    name="right_leg_pelvic_yaw_link">
    <inertial>
      <origin
        xyz="-0.00780257 -0.00226954 -0.16353327"
        rpy="0 0 0" />
      <mass
        value="3.75131864" />
      <inertia
        ixx="0.05584376"
        ixy="0.00022202"
        ixz="0.00347109"
        iyy="0.05697673"
        iyz="0.00106339"
        izz="0.00478229" />
    </inertial>
    <visual>
      <origin
        xyz="0 0 0"
        rpy="0 0 0" />
      <geometry>
        <mesh
          filename="../meshes/right_leg_pelvic_yaw_link.STL" />
      </geometry>
      <material
        name="">
        <color
          rgba="0.792156862745098 0.819607843137255 0.933333333333333 1" />
      </material>
    </visual>
    <collision>
      <origin
        xyz="0 0 0"
        rpy="0 0 0" />
      <geometry>
        <mesh
          filename="../meshes/right_leg_pelvic_yaw_link.STL" />
      </geometry>
    </collision>
  </link>
  <joint
    name="right_leg_pelvic_yaw_joint"
    type="revolute">
    <origin
      xyz="0 0 -0.0975"
      rpy="0 0 0" />
    <parent
      link="right_leg_pelvic_roll_link" />
    <child
      link="right_leg_pelvic_yaw_link" />
    <axis
      xyz="0 0 1" />
    <limit
      lower="-1.5708"
      upper="1.5708"
      effort="0"
      velocity="0" />
  </joint>
  <link
    name="right_leg_knee_pitch_link">
    <inertial>
      <origin
        xyz="0.0034152 0.0026614 -0.19654"
        rpy="0 0 0" />
      <mass
        value="3.705" />
      <inertia
        ixx="0.042318"
        ixy="-5.758E-05"
        ixz="0.0017314"
        iyy="0.042443"
        iyz="0.0015236"
        izz="0.0039701" />
    </inertial>
    <visual>
      <origin
        xyz="0 0 0"
        rpy="0 0 0" />
      <geometry>
        <mesh
          filename="../meshes/right_leg_knee_pitch_link.STL" />
      </geometry>
      <material
        name="">
        <color
          rgba="0.79216 0.81961 0.93333 1" />
      </material>
    </visual>
    <collision>
      <origin
        xyz="0 0 0"
        rpy="0 0 0" />
      <geometry>
        <mesh
          filename="../meshes/right_leg_knee_pitch_link.STL" />
      </geometry>
    </collision>
  </link>
  <joint
    name="right_leg_knee_pitch_joint"
    type="revolute">
    <origin
      xyz="-0.02 0 -0.2735"
      rpy="0 0 0" />
    <parent
      link="right_leg_pelvic_yaw_link" />
    <child
      link="right_leg_knee_pitch_link" />
    <axis
      xyz="0 1 0" />
    <limit
      lower="0"
      upper="2.5307"
      effort="0"
      velocity="0" />
  </joint>
  <link
    name="right_leg_ankle_pitch_link">
    <inertial>
      <origin
        xyz="0 -1.93E-06 0"
        rpy="0 0 0" />
      <mass
        value="0.05737571" />
      <inertia
        ixx="1.172E-05"
        ixy="0"
        ixz="0"
        iyy="9.47E-06"
        iyz="0"
        izz="1.044E-05" />
    </inertial>
    <visual>
      <origin
        xyz="0 0 0"
        rpy="0 0 0" />
      <geometry>
        <mesh
          filename="../meshes/right_leg_ankle_pitch_link.STL" />
      </geometry>
      <material
        name="">
        <color
          rgba="0.792156862745098 0.819607843137255 0.933333333333333 1" />
      </material>
    </visual>
    <collision>
      <origin
        xyz="0 0 0"
        rpy="0 0 0" />
      <geometry>
        <mesh
          filename="../meshes/right_leg_ankle_pitch_link.STL" />
      </geometry>
    </collision>
  </link>
  <joint
    name="right_leg_ankle_pitch_joint"
    type="revolute">
    <origin
      xyz="0 0 -0.453"
      rpy="0 0 0" />
    <parent
      link="right_leg_knee_pitch_link" />
    <child
      link="right_leg_ankle_pitch_link" />
    <axis
      xyz="0 1 0" />
    <limit
      lower="-0.87266"
      upper="0.50614"
      effort="0"
      velocity="0" />
  </joint>
  <link
    name="right_leg_ankle_roll_link">
    <inertial>
      <origin
        xyz="0.01951212 -0.00117074 -0.03361118"
        rpy="0 0 0" />
      <mass
        value="0.88244453" />
      <inertia
        ixx="0.001165"
        ixy="-8.769E-05"
        ixz="-0.00027222"
        iyy="0.00448399"
        iyz="1.053E-05"
        izz="0.00477071" />
    </inertial>
    <visual>
      <origin
        xyz="0 0 0"
        rpy="0 0 0" />
      <geometry>
        <mesh
          filename="../meshes/right_leg_ankle_roll_link.STL" />
      </geometry>
      <material
        name="">
        <color
          rgba="0.792156862745098 0.819607843137255 0.933333333333333 1" />
      </material>
    </visual>
    <collision>
      <origin
        xyz="0 0 0"
        rpy="0 0 0" />
      <geometry>
        <mesh
          filename="../meshes/right_leg_ankle_roll_link.STL" />
      </geometry>
    </collision>
  </link>
  <joint
    name="right_leg_ankle_roll_joint"
    type="revolute">
    <origin
      xyz="0 0 0"
      rpy="0 0 0" />
    <parent
      link="right_leg_ankle_pitch_link" />
    <child
      link="right_leg_ankle_roll_link" />
    <axis
      xyz="1 0 0" />
    <limit
      lower="-0.50614"
      upper="0.50614"
      effort="0"
      velocity="0" />
  </joint>
  <link
    name="waist_yaw_link">
    <inertial>
      <origin
        xyz="-0.01696961 7.138E-05 0.18492754"
        rpy="0 0 0" />
      <mass
        value="9.10349623" />
      <inertia
        ixx="0.10493626"
        ixy="0.00011467"
        ixz="-0.00252168"
        iyy="0.09660739"
        iyz="0.00019585"
        izz="0.05412755" />
    </inertial>
    <visual>
      <origin
        xyz="0 0 0"
        rpy="0 0 0" />
      <geometry>
        <mesh
          filename="../meshes/waist_yaw_link.STL" />
      </geometry>
      <material
        name="">
        <color
          rgba="0.792156862745098 0.819607843137255 0.933333333333333 1" />
      </material>
    </visual>
    <collision>
      <origin
        xyz="0 0 0"
        rpy="0 0 0" />
      <geometry>
        <mesh
          filename="../meshes/waist_yaw_link.STL" />
      </geometry>
    </collision>
  </link>
  <joint
    name="waist_yaw_joint"
    type="revolute">
    <origin
      xyz="0 0 0.15424"
      rpy="0 0 0" />
    <parent
      link="base_link" />
    <child
      link="waist_yaw_link" />
    <axis
      xyz="0 0 1" />
    <limit
      lower="-1.5708"
      upper="1.5708"
      effort="0"
      velocity="0" />
  </joint>
  <link
    name="head_yaw_link">
    <inertial>
      <origin
        xyz="-0.00013343 0.00165492 0.04351026"
        rpy="0 0 0" />
      <mass
        value="0.4693911" />
      <inertia
        ixx="0.00016197"
        ixy="1.11E-06"
        ixz="-3.33E-06"
        iyy="0.00013128"
        iyz="7.4E-06"
        izz="0.00013406" />
    </inertial>
    <visual>
      <origin
        xyz="0 0 0"
        rpy="0 0 0" />
      <geometry>
        <mesh
          filename="../meshes/head_yaw_link.STL" />
      </geometry>
      <material
        name="">
        <color
          rgba="0.792156862745098 0.819607843137255 0.933333333333333 1" />
      </material>
    </visual>
    <collision>
      <origin
        xyz="0 0 0"
        rpy="0 0 0" />
      <geometry>
        <mesh
          filename="../meshes/head_yaw_link.STL" />
      </geometry>
    </collision>
  </link>
  <joint
    name="head_yaw_joint"
    type="revolute">
    <origin
      xyz="0 0 0.3623"
      rpy="0 0 0" />
    <parent
      link="waist_yaw_link" />
    <child
      link="head_yaw_link" />
    <axis
      xyz="0 0 1" />
    <limit
      lower="-1.5708"
      upper="1.5708"
      effort="0"
      velocity="0" />
  </joint>
  <link
    name="head_pitch_link">
    <inertial>
      <origin
        xyz="0.02864075 -0.00329851 0.06968176"
        rpy="0 0 0" />
      <mass
        value="0.47326384" />
      <inertia
        ixx="0.00109306"
        ixy="2.61E-05"
        ixz="-0.00012458"
        iyy="0.00118211"
        iyz="6.526E-05"
        izz="0.00092172" />
    </inertial>
    <visual>
      <origin
        xyz="0 0 0"
        rpy="0 0 0" />
      <geometry>
        <mesh
          filename="../meshes/head_pitch_link.STL" />
      </geometry>
      <material
        name="">
        <color
          rgba="0.792156862745098 0.819607843137255 0.933333333333333 1" />
      </material>
    </visual>
    <collision>
      <origin
        xyz="0 0 0"
        rpy="0 0 0" />
      <geometry>
        <mesh
          filename="../meshes/head_pitch_link.STL" />
      </geometry>
    </collision>
  </link>
  <joint
    name="head_pitch_joint"
    type="revolute">
    <origin
      xyz="0 0 0.046"
      rpy="0 0 0" />
    <parent
      link="head_yaw_link" />
    <child
      link="head_pitch_link" />
    <axis
      xyz="0 1 0" />
    <limit
      lower="-0.2618"
      upper="0.5236"
      effort="0"
      velocity="0" />
  </joint>
  <link
    name="left_shoulder_pitch_link">
    <inertial>
      <origin
        xyz="0.00759901 0.05126151 8.961E-05"
        rpy="0 0 0" />
      <mass
        value="0.64930498" />
      <inertia
        ixx="0.00028959"
        ixy="3.295E-05"
        ixz="-1.23E-06"
        iyy="0.00025914"
        iyz="-1.72E-06"
        izz="0.00037199" />
    </inertial>
    <visual>
      <origin
        xyz="0 0 0"
        rpy="0 0 0" />
      <geometry>
        <mesh
          filename="../meshes/left_shoulder_pitch_link.STL" />
      </geometry>
      <material
        name="">
        <color
          rgba="0.792156862745098 0.819607843137255 0.933333333333333 1" />
      </material>
    </visual>
    <collision>
      <origin
        xyz="0 0 0"
        rpy="0 0 0" />
      <geometry>
        <mesh
          filename="../meshes/left_shoulder_pitch_link.STL" />
      </geometry>
    </collision>
  </link>
  <joint
    name="left_shoulder_pitch_joint"
    type="revolute">
    <origin
      xyz="0 0.145 0.2673"
      rpy="0 0 0" />
    <parent
      link="waist_yaw_link" />
    <child
      link="left_shoulder_pitch_link" />
    <axis
      xyz="0 1 0" />
    <limit
      lower="-3.1416"
      upper="1.0472"
      effort="0"
      velocity="0" />
  </joint>
  <link
    name="left_shoulder_roll_link">
    <inertial>
      <origin
        xyz="1.11E-06 -0.00020652 -0.08597528"
        rpy="0 0 0" />
      <mass
        value="0.60983778" />
      <inertia
        ixx="0.00078122"
        ixy="1.3E-07"
        ixz="8.27E-06"
        iyy="0.00091878"
        iyz="5.89E-06"
        izz="0.00029222" />
    </inertial>
    <visual>
      <origin
        xyz="0 0 0"
        rpy="0 0 0" />
      <geometry>
        <mesh
          filename="../meshes/left_shoulder_roll_link.STL" />
      </geometry>
      <material
        name="">
        <color
          rgba="0.792156862745098 0.819607843137255 0.933333333333333 1" />
      </material>
    </visual>
    <collision>
      <origin
        xyz="0 0 0"
        rpy="0 0 0" />
      <geometry>
        <mesh
          filename="../meshes/left_shoulder_roll_link.STL" />
      </geometry>
    </collision>
  </link>
  <joint
    name="left_shoulder_roll_joint"
    type="revolute">
    <origin
      xyz="0 0.057 0"
      rpy="0 0 0" />
    <parent
      link="left_shoulder_pitch_link" />
    <child
      link="left_shoulder_roll_link" />
    <axis
      xyz="1 0 0" />
    <limit
      lower="-0.3491"
      upper="3.1416"
      effort="0"
      velocity="0" />
  </joint>
  <link
    name="left_shoulder_yaw_link">
    <inertial>
      <origin
        xyz="2.838E-05 0.02000113 -0.02788264"
        rpy="0 0 0" />
      <mass
        value="0.07883639" />
      <inertia
        ixx="7.362E-05"
        ixy="2E-08"
        ixz="-2.1E-07"
        iyy="6.074E-05"
        iyz="-2.158E-05"
        izz="2.933E-05" />
    </inertial>
    <visual>
      <origin
        xyz="0 0 0"
        rpy="0 0 0" />
      <geometry>
        <mesh
          filename="../meshes/left_shoulder_yaw_link.STL" />
      </geometry>
      <material
        name="">
        <color
          rgba="0.792156862745098 0.819607843137255 0.933333333333333 1" />
      </material>
    </visual>
    <collision>
      <origin
        xyz="0 0 0"
        rpy="0 0 0" />
      <geometry>
        <mesh
          filename="../meshes/left_shoulder_yaw_link.STL" />
      </geometry>
    </collision>
  </link>
  <joint
    name="left_shoulder_yaw_joint"
    type="revolute">
    <origin
      xyz="0 0 -0.1315"
      rpy="0 0 0" />
    <parent
      link="left_shoulder_roll_link" />
    <child
      link="left_shoulder_yaw_link" />
    <axis
      xyz="0 0 1" />
    <limit
      lower="-1.5708"
      upper="1.5708"
      effort="0"
      velocity="0" />
  </joint>
  <link
    name="left_elbow_pitch_link">
    <inertial>
      <origin
        xyz="-0.00050872 -0.00152061 -0.04453537"
        rpy="0 0 0" />
      <mass
        value="1.01311466" />
      <inertia
        ixx="0.0025769"
        ixy="-1.377E-05"
        ixz="-4.48E-06"
        iyy="0.00249467"
        iyz="-9.445E-05"
        izz="0.00028815" />
    </inertial>
    <visual>
      <origin
        xyz="0 0 0"
        rpy="0 0 0" />
      <geometry>
        <mesh
          filename="../meshes/left_elbow_pitch_link.STL" />
      </geometry>
      <material
        name="">
        <color
          rgba="0.792156862745098 0.819607843137255 0.933333333333333 1" />
      </material>
    </visual>
    <collision>
      <origin
        xyz="0 0 0"
        rpy="0 0 0" />
      <geometry>
        <mesh
          filename="../meshes/left_elbow_pitch_link.STL" />
      </geometry>
    </collision>
  </link>
  <joint
    name="left_elbow_pitch_joint"
    type="revolute">
    <origin
      xyz="0 0 -0.061"
      rpy="0 0 0" />
    <parent
      link="left_shoulder_yaw_link" />
    <child
      link="left_elbow_pitch_link" />
    <axis
      xyz="0 1 0" />
    <limit
      lower="-1.8675"
      upper="0"
      effort="0"
      velocity="0" />
  </joint>
  <link
    name="left_wrist_yaw_link">
    <inertial>
      <origin
        xyz="0.00066742 -0.00325051 -0.03139976"
        rpy="0 0 0" />
      <mass
        value="0.12440601" />
      <inertia
        ixx="0.00013262"
        ixy="-1.8E-07"
        ixz="9.8E-07"
        iyy="0.00013609"
        iyz="2.81E-06"
        izz="2.114E-05" />
    </inertial>
    <visual>
      <origin
        xyz="0 0 0"
        rpy="0 0 0" />
      <geometry>
        <mesh
          filename="../meshes/left_wrist_yaw_link.STL" />
      </geometry>
      <material
        name="">
        <color
          rgba="0.792156862745098 0.819607843137255 0.933333333333333 1" />
      </material>
    </visual>
    <collision>
      <origin
        xyz="0 0 0"
        rpy="0 0 0" />
      <geometry>
        <mesh
          filename="../meshes/left_wrist_yaw_link.STL" />
      </geometry>
    </collision>
  </link>
  <joint
    name="left_wrist_yaw_joint"
    type="revolute">
    <origin
      xyz="0 0 -0.131"
      rpy="0 0 0" />
    <parent
      link="left_elbow_pitch_link" />
    <child
      link="left_wrist_yaw_link" />
    <axis
      xyz="0 0 1" />
    <limit
      lower="-1.5708"
      upper="1.5708"
      effort="0"
      velocity="0" />
  </joint>
  <link
    name="right_shoulder_pitch_link">
    <inertial>
      <origin
        xyz="0.00755271 -0.05111385 4.648E-05"
        rpy="0 0 0" />
      <mass
        value="0.65209572" />
      <inertia
        ixx="0.00029654"
        ixy="-3.321E-05"
        ixz="-1.9E-07"
        iyy="0.0002609"
        iyz="2.24E-06"
        izz="0.00037849" />
    </inertial>
    <visual>
      <origin
        xyz="0 0 0"
        rpy="0 0 0" />
      <geometry>
        <mesh
          filename="../meshes/right_shoulder_pitch_link.STL" />
      </geometry>
      <material
        name="">
        <color
          rgba="0.792156862745098 0.819607843137255 0.933333333333333 1" />
      </material>
    </visual>
    <collision>
      <origin
        xyz="0 0 0"
        rpy="0 0 0" />
      <geometry>
        <mesh
          filename="../meshes/right_shoulder_pitch_link.STL" />
      </geometry>
    </collision>
  </link>
  <joint
    name="right_shoulder_pitch_joint"
    type="revolute">
    <origin
      xyz="0 -0.145 0.2673"
      rpy="0 0 0" />
    <parent
      link="waist_yaw_link" />
    <child
      link="right_shoulder_pitch_link" />
    <axis
      xyz="0 1 0" />
    <limit
      lower="-3.1416"
      upper="1.0472"
      effort="0"
      velocity="0" />
  </joint>
  <link
    name="right_shoulder_roll_link">
    <inertial>
      <origin
        xyz="1.294E-05 0.00019306 -0.08594396"
        rpy="0 0 0" />
      <mass
        value="0.61051121" />
      <inertia
        ixx="0.00078187"
        ixy="1.3E-07"
        ixz="8.84E-06"
        iyy="0.00091979"
        iyz="-6.43E-06"
        izz="0.00029279" />
    </inertial>
    <visual>
      <origin
        xyz="0 0 0"
        rpy="0 0 0" />
      <geometry>
        <mesh
          filename="../meshes/right_shoulder_roll_link.STL" />
      </geometry>
      <material
        name="">
        <color
          rgba="0.792156862745098 0.819607843137255 0.933333333333333 1" />
      </material>
    </visual>
    <collision>
      <origin
        xyz="0 0 0"
        rpy="0 0 0" />
      <geometry>
        <mesh
          filename="../meshes/right_shoulder_roll_link.STL" />
      </geometry>
    </collision>
  </link>
  <joint
    name="right_shoulder_roll_joint"
    type="revolute">
    <origin
      xyz="0 -0.057 0"
      rpy="0 0 0" />
    <parent
      link="right_shoulder_pitch_link" />
    <child
      link="right_shoulder_roll_link" />
    <axis
      xyz="1 0 0" />
    <limit
      lower="-3.1416"
      upper="0.3491"
      effort="0"
      velocity="0" />
  </joint>
  <link
    name="right_shoulder_yaw_link">
    <inertial>
      <origin
        xyz="-2.838E-05 -0.020001 -0.027883"
        rpy="0 0 0" />
      <mass
        value="0.078836" />
      <inertia
        ixx="7.362E-05"
        ixy="2E-08"
        ixz="2.1E-07"
        iyy="6.074E-05"
        iyz="2.158E-05"
        izz="2.933E-05" />
    </inertial>
    <visual>
      <origin
        xyz="0 0 0"
        rpy="0 0 0" />
      <geometry>
        <mesh
          filename="../meshes/right_shoulder_yaw_link.STL" />
      </geometry>
      <material
        name="">
        <color
          rgba="0.79216 0.81961 0.93333 1" />
      </material>
    </visual>
    <collision>
      <origin
        xyz="0 0 0"
        rpy="0 0 0" />
      <geometry>
        <mesh
          filename="../meshes/right_shoulder_yaw_link.STL" />
      </geometry>
    </collision>
  </link>
  <joint
    name="right_shoulder_yaw_joint"
    type="revolute">
    <origin
      xyz="0 0 -0.1315"
      rpy="0 0 0" />
    <parent
      link="right_shoulder_roll_link" />
    <child
      link="right_shoulder_yaw_link" />
    <axis
      xyz="0 0 1" />
    <limit
      lower="-1.5708"
      upper="1.5708"
      effort="0"
      velocity="0" />
  </joint>
  <link
    name="right_elbow_pitch_link">
    <inertial>
      <origin
        xyz="-0.0002278 0.00151852 -0.04454802"
        rpy="0 0 0" />
      <mass
        value="1.0134885" />
      <inertia
        ixx="0.00257755"
        ixy="1.16E-05"
        ixz="-2.749E-05"
        iyy="0.00249544"
        iyz="9.442E-05"
        izz="0.00028869" />
    </inertial>
    <visual>
      <origin
        xyz="0 0 0"
        rpy="0 0 0" />
      <geometry>
        <mesh
          filename="../meshes/right_elbow_pitch_link.STL" />
      </geometry>
      <material
        name="">
        <color
          rgba="0.792156862745098 0.819607843137255 0.933333333333333 1" />
      </material>
    </visual>
    <collision>
      <origin
        xyz="0 0 0"
        rpy="0 0 0" />
      <geometry>
        <mesh
          filename="../meshes/right_elbow_pitch_link.STL" />
      </geometry>
    </collision>
  </link>
  <joint
    name="right_elbow_pitch_joint"
    type="revolute">
    <origin
      xyz="0 0 -0.061"
      rpy="0 0 0" />
    <parent
      link="right_shoulder_yaw_link" />
    <child
      link="right_elbow_pitch_link" />
    <axis
      xyz="0 1 0" />
    <limit
      lower="-1.8675"
      upper="0"
      effort="0"
      velocity="0" />
  </joint>
  <link
    name="right_wrist_yaw_link">
    <inertial>
      <origin
        xyz="-0.00066742 0.00325051 -0.03439976"
        rpy="0 0 0" />
      <mass
        value="0.12440601" />
      <inertia
        ixx="0.00013262"
        ixy="-1.8E-07"
        ixz="-9.8E-07"
        iyy="0.00013609"
        iyz="-2.81E-06"
        izz="2.114E-05" />
    </inertial>
    <visual>
      <origin
        xyz="0 0 0"
        rpy="0 0 0" />
      <geometry>
        <mesh
          filename="../meshes/right_wrist_yaw_link.STL" />
      </geometry>
      <material
        name="">
        <color
          rgba="0.792156862745098 0.819607843137255 0.933333333333333 1" />
      </material>
    </visual>
    <collision>
      <origin
        xyz="0 0 0"
        rpy="0 0 0" />
      <geometry>
        <mesh
          filename="../meshes/right_wrist_yaw_link.STL" />
      </geometry>
    </collision>
  </link>
  <joint
    name="right_wrist_yaw_joint"
    type="revolute">
    <origin
      xyz="0 0 -0.128"
      rpy="0 0 0" />
    <parent
      link="right_elbow_pitch_link" />
    <child
      link="right_wrist_yaw_link" />
    <axis
      xyz="0 0 1" />
    <limit
      lower="-1.5708"
      upper="1.5708"
      effort="0"
      velocity="0" />
  </joint>
</robot>