<mujoco model="CB02_URDF_ECS_WK_0904B">
  <compiler angle="radian" meshdir="meshes/"/>

  <asset>
    <texture type="skybox" builtin="gradient" rgb1=".3 .5 .7" rgb2="0 0 0" width="32" height="512" />
    <texture name="body" type="cube" builtin="flat" mark="cross" width="128" height="128"
      rgb1="0.8 0.6 0.4" rgb2="0.8 0.6 0.4" markrgb="1 1 1" random="0.01" />
    <material name="body" texture="body" texuniform="true" rgba="0.8 0.6 .4 1" />
    <texture name="grid" type="2d" builtin="checker" width="512" height="512" rgb1=".1 .2 .3"
      rgb2=".2 .3 .4" />
    <material name="grid" texture="grid" texrepeat="1 1" texuniform="true" reflectance=".2" />
  </asset>

  <default>
    <joint damping="0.01" armature="0.01" frictionloss="0.01"/>
  </default>

  <asset>
    <mesh name="base_link" file="base_link.STL"/>
    <mesh name="left_leg_pelvic_pitch_link" file="left_leg_pelvic_pitch_link.STL"/>
    <mesh name="left_leg_pelvic_roll_link" file="left_leg_pelvic_roll_link.STL"/>
    <mesh name="left_leg_pelvic_yaw_link" file="left_leg_pelvic_yaw_link.STL"/>
    <mesh name="left_leg_knee_pitch_link" file="left_leg_knee_pitch_link.STL"/>
    <mesh name="left_leg_ankle_pitch_link" file="left_leg_ankle_pitch_link.STL"/>
    <mesh name="left_leg_ankle_roll_link" file="left_leg_ankle_roll_link.STL"/>
    <mesh name="right_leg_pelvic_pitch_link" file="right_leg_pelvic_pitch_link.STL"/>
    <mesh name="right_leg_pelvic_roll_link" file="right_leg_pelvic_roll_link.STL"/>
    <mesh name="right_leg_pelvic_yaw_link" file="right_leg_pelvic_yaw_link.STL"/>
    <mesh name="right_leg_knee_pitch_link" file="right_leg_knee_pitch_link.STL"/>
    <mesh name="right_leg_ankle_pitch_link" file="right_leg_ankle_pitch_link.STL"/>
    <mesh name="right_leg_ankle_roll_link" file="right_leg_ankle_roll_link.STL"/>
    <mesh name="waist_yaw_link" file="waist_yaw_link.STL"/>
    <mesh name="head_yaw_link" file="head_yaw_link.STL"/>
    <mesh name="head_pitch_link" file="head_pitch_link.STL"/>
    <mesh name="left_shoulder_pitch_link" file="left_shoulder_pitch_link.STL"/>
    <mesh name="left_shoulder_roll_link" file="left_shoulder_roll_link.STL"/>
    <mesh name="left_shoulder_yaw_link" file="left_shoulder_yaw_link.STL"/>
    <mesh name="left_elbow_pitch_link" file="left_elbow_pitch_link.STL"/>
    <mesh name="left_wrist_yaw_link" file="left_wrist_yaw_link.STL"/>
    <mesh name="right_shoulder_pitch_link" file="right_shoulder_pitch_link.STL"/>
    <mesh name="right_shoulder_roll_link" file="right_shoulder_roll_link.STL"/>
    <mesh name="right_shoulder_yaw_link" file="right_shoulder_yaw_link.STL"/>
    <mesh name="right_elbow_pitch_link" file="right_elbow_pitch_link.STL"/>
    <mesh name="right_wrist_yaw_link" file="right_wrist_yaw_link.STL"/>
  </asset>

  <worldbody>
    <geom name="ground" type="plane" pos="0 0 0" size="10 10 0.1" material="grid" condim="3" />
    <light name="main_light" pos="0 -3 5" dir="0 1 -1" diffuse="1 1 1" specular="0.5 0.5 0.5" directional="true" castshadow="true" />
    <body name="base_link" pos="0 0 0.868" quat="1 0 0 0">
      <inertial pos="0.00090049 3.158E-05 0.059413" mass="4.478" diaginertia="0.013418 0.0086488 0.011258"/>
      <freejoint name="base_link"/>
      <site name="imu"  pos="0.0 0 0.0" quat="1 0 0 0" size="0.078" rgba="255 0 0 1"/>
      <geom type="mesh" mesh="base_link" rgba="0.79216 0.81961 0.93333 1"/>
      <geom type="mesh" mesh="base_link" rgba="0.79216 0.81961 0.93333 1" group="1"/>
      <body name="left_leg_pelvic_pitch_link" pos="0 0.061 0.0575">
        <inertial pos="0.007392 0.0735787 -0.0476224" quat="0.407442 0.910672 -0.0585159 0.0352733" mass="2.16712" diaginertia="0.00390966 0.00329264 0.00186876"/>
        <joint name="left_leg_pelvic_pitch_joint" pos="0 0 0" axis="0 1 0" range="-1.9199 1.5708"/>
        <geom type="mesh" rgba="0.792157 0.819608 0.933333 1" mesh="left_leg_pelvic_pitch_link"/>
        <body name="left_leg_pelvic_roll_link" pos="-0.0028 0.0815 -0.055">
          <inertial pos="0.0317977 1.95e-05 -0.0477515" quat="0.98688 -0.00194293 -0.161011 -0.0118421" mass="0.494852" diaginertia="0.00116108 0.00109256 0.000369379"/>
          <joint name="left_leg_pelvic_roll_joint" pos="0 0 0" axis="1 0 0" range="-0.17453 1.5708"/>
          <geom type="mesh" rgba="0.792157 0.819608 0.933333 1" mesh="left_leg_pelvic_roll_link"/>
          <body name="left_leg_pelvic_yaw_link" pos="0 0 -0.0975">
            <inertial pos="-0.00776171 0.00252331 -0.166394" quat="0.595531 -0.03466 -0.013831 0.802465" mass="3.67359" diaginertia="0.0549996 0.0539441 0.00435641"/>
            <joint name="left_leg_pelvic_yaw_joint" pos="0 0 0" axis="0 0 1" range="-1.5708 1.5708"/>
            <geom type="mesh" rgba="0.792157 0.819608 0.933333 1" mesh="left_leg_pelvic_yaw_link"/>
            <body name="left_leg_knee_pitch_link" pos="-0.02 0 -0.2735">
              <inertial pos="0.00342465 -0.00267008 -0.196705" quat="0.672917 -0.0298664 -0.000587356 0.739114" mass="3.70154" diaginertia="0.0426134 0.0424999 0.00382652"/>
              <joint name="left_leg_knee_pitch_joint" pos="0 0 0" axis="0 1 0" range="0 2.5307"/>
              <geom type="mesh" rgba="0.792157 0.819608 0.933333 1" mesh="left_leg_knee_pitch_link"/>
              <body name="left_leg_ankle_pitch_link" pos="0 0 -0.453">
                <inertial pos="0 -1.93e-06 0" quat="0.707107 0.707107 0 0" mass="0.0573757" diaginertia="1.172e-05 1.044e-05 9.47e-06"/>
                <joint name="left_leg_ankle_pitch_joint" pos="0 0 0" axis="0 1 0" range="-0.87266 0.50614"/>
                <geom type="mesh" rgba="0.792157 0.819608 0.933333 1" mesh="left_leg_ankle_pitch_link"/>
                <body name="left_leg_ankle_roll_link">
                  <inertial pos="0.0187444 0.00117256 -0.0409485" quat="-0.0190107 0.668942 -0.0359937 0.742199" mass="0.882585" diaginertia="0.0045177 0.00422814 0.00101679"/>
                  <joint name="left_leg_ankle_roll_joint" pos="0 0 0" axis="1 0 0" range="-0.50614 0.50614"/>
                  <geom type="mesh" rgba="0.792157 0.819608 0.933333 1" mesh="left_leg_ankle_roll_link"/>
                </body>
              </body>
            </body>
          </body>
        </body>
      </body>
      <body name="right_leg_pelvic_pitch_link" pos="0 -0.061 0.0575">
        <inertial pos="0.00736841 -0.0735154 -0.0475662" quat="0.910954 0.407365 -0.033918 0.0553693" mass="2.1692" diaginertia="0.00392629 0.0033128 0.00187006"/>
        <joint name="right_leg_pelvic_pitch_joint" pos="0 0 0" axis="0 1 0" range="-1.9199 1.5708"/>
        <geom type="mesh" rgba="0.792157 0.819608 0.933333 1" mesh="right_leg_pelvic_pitch_link"/>
        <body name="right_leg_pelvic_roll_link" pos="-0.0028 -0.0815 -0.055">
          <inertial pos="0.0317977 1.95e-05 -0.0477515" quat="0.98688 -0.00194293 -0.161011 -0.0118421" mass="0.494852" diaginertia="0.00116108 0.00109256 0.000369379"/>
          <joint name="right_leg_pelvic_roll_joint" pos="0 0 0" axis="1 0 0" range="-1.5708 0.17453"/>
          <geom type="mesh" rgba="0.792157 0.819608 0.933333 1" mesh="right_leg_pelvic_roll_link"/>
          <body name="right_leg_pelvic_yaw_link" pos="0 0 -0.0975">
            <inertial pos="-0.00780257 -0.00226954 -0.163533" quat="0.799373 -0.0122552 -0.0329539 0.599806" mass="3.75132" diaginertia="0.0570832 0.055993 0.00452655"/>
            <joint name="right_leg_pelvic_yaw_joint" pos="0 0 0" axis="0 0 1" range="-1.5708 1.5708"/>
            <geom type="mesh" rgba="0.792157 0.819608 0.933333 1" mesh="right_leg_pelvic_yaw_link"/>
            <body name="right_leg_knee_pitch_link" pos="-0.02 0 -0.2735">
              <inertial pos="0.0034152 0.0026614 -0.19654" quat="0.741493 -0.000441867 -0.029922 0.670293" mass="3.705" diaginertia="0.0425043 0.0423949 0.00383188"/>
              <joint name="right_leg_knee_pitch_joint" pos="0 0 0" axis="0 1 0" range="0 2.5307"/>
              <geom type="mesh" rgba="0.79216 0.81961 0.93333 1" mesh="right_leg_knee_pitch_link"/>
              <body name="right_leg_ankle_pitch_link" pos="0 0 -0.453">
                <inertial pos="0 -1.93e-06 0" quat="0.707107 0.707107 0 0" mass="0.0573757" diaginertia="1.172e-05 1.044e-05 9.47e-06"/>
                <joint name="right_leg_ankle_pitch_joint" pos="0 0 0" axis="0 1 0" range="-0.87266 0.50614"/>
                <geom type="mesh" rgba="0.792157 0.819608 0.933333 1" mesh="right_leg_ankle_pitch_link"/>
                <body name="right_leg_ankle_roll_link">
                  <inertial pos="0.0195121 -0.00117074 -0.0336112" quat="0.011605 0.679583 0.0284444 0.732955" mass="0.882445" diaginertia="0.0047921 0.00448529 0.00114232"/>
                  <joint name="right_leg_ankle_roll_joint" pos="0 0 0" axis="1 0 0" range="-0.50614 0.50614"/>
                  <geom type="mesh" rgba="0.792157 0.819608 0.933333 1" mesh="right_leg_ankle_roll_link"/>
                </body>
              </body>
            </body>
          </body>
        </body>
      </body>
      <body name="waist_yaw_link" pos="0 0 0.15424">
        <inertial pos="-0.0169696 7.138e-05 0.184928" quat="0.999672 0.00251467 0.0247215 0.00614013" mass="9.1035" diaginertia="0.105062 0.096607 0.0540018"/>
        <joint name="waist_yaw_joint" pos="0 0 0" axis="0 0 1" range="-1.5708 1.5708"/>
        <geom type="mesh" rgba="0.792157 0.819608 0.933333 1" mesh="waist_yaw_link"/>
        <body name="head_yaw_link" pos="0 0 0.3623">
          <inertial pos="-0.00013343 0.00165492 0.0435103" quat="0.906391 0.418493 0.0538848 -0.0203793" mass="0.469391" diaginertia="0.000162364 0.000140047 0.000124899"/>
          <joint name="head_yaw_joint" pos="0 0 0" axis="0 0 1" range="-1.5708 1.5708"/>
          <geom type="mesh" rgba="0.792157 0.819608 0.933333 1" mesh="head_yaw_link"/>
          <body name="head_pitch_link" pos="0 0 0.046">
            <inertial pos="0.0286407 -0.00329851 0.0696818" quat="0.637964 0.244314 0.0759975 0.726317" mass="0.473264" diaginertia="0.00119777 0.00115729 0.000841827"/>
            <joint name="head_pitch_joint" pos="0 0 0" axis="0 1 0" range="-0.2618 0.5236"/>
            <geom type="mesh" rgba="0.792157 0.819608 0.933333 1" mesh="head_pitch_link"/>
          </body>
        </body>
        <body name="left_shoulder_pitch_link" pos="0 0.145 0.2673">
          <inertial pos="0.00759901 0.0512615 8.961e-05" quat="0.328695 0.616506 -0.35051 0.623717" mass="0.649305" diaginertia="0.000372057 0.0003106 0.000238063"/>
          <joint name="left_shoulder_pitch_joint" pos="0 0 0" axis="0 1 0" range="-3.1416 1.0472"/>
          <geom type="mesh" rgba="0.792157 0.819608 0.933333 1" mesh="left_shoulder_pitch_link"/>
          <body name="left_shoulder_roll_link" pos="0 0.057 0">
            <inertial pos="1.11e-06 -0.00020652 -0.0859753" quat="0.707636 -0.00264697 -0.00929817 0.706511" mass="0.609838" diaginertia="0.000918836 0.000781359 0.000292025"/>
            <joint name="left_shoulder_roll_joint" pos="0 0 0" axis="1 0 0" range="-0.3491 3.1416"/>
            <geom type="mesh" rgba="0.792157 0.819608 0.933333 1" mesh="left_shoulder_roll_link"/>
            <body name="left_shoulder_yaw_link" pos="0 0 -0.1315">
              <inertial pos="2.838e-05 0.0200011 -0.0278826" quat="0.971999 -0.233099 0.00848888 0.0284864" mass="0.0788364" diaginertia="7.36273e-05 7.1718e-05 1.83447e-05"/>
              <joint name="left_shoulder_yaw_joint" pos="0 0 0" axis="0 0 1" range="-1.5708 1.5708"/>
              <geom type="mesh" rgba="0.792157 0.819608 0.933333 1" mesh="left_shoulder_yaw_link"/>
              <body name="left_elbow_pitch_link" pos="0 0 -0.061">
                <inertial pos="-0.00050872 -0.00152061 -0.0445354" quat="0.996287 -0.0213732 -0.000680601 -0.0833931" mass="1.01311" diaginertia="0.0025792 0.00249642 0.000284103"/>
                <joint name="left_elbow_pitch_joint" pos="0 0 0" axis="0 1 0" range="-1.8675 0"/>
                <geom type="mesh" rgba="0.792157 0.819608 0.933333 1" mesh="left_elbow_pitch_link"/>
                <body name="left_wrist_yaw_link" pos="0 0 -0.131">
                  <inertial pos="0.00066742 -0.00325051 -0.0313998" quat="0.691332 0.00526097 -0.011877 0.72242" mass="0.124406" diaginertia="0.000136166 0.000132622 2.10627e-05"/>
                  <joint name="left_wrist_yaw_joint" pos="0 0 0" axis="0 0 1" range="-1.5708 1.5708"/>
                  <geom type="mesh" rgba="0.792157 0.819608 0.933333 1" mesh="left_wrist_yaw_link"/>
                </body>
              </body>
            </body>
          </body>
        </body>
        <body name="right_shoulder_pitch_link" pos="0 -0.145 0.2673">
          <inertial pos="0.00755271 -0.0511139 4.648e-05" quat="0.615388 0.340055 -0.614594 0.357678" mass="0.652096" diaginertia="0.000378542 0.000316381 0.000241007"/>
          <joint name="right_shoulder_pitch_joint" pos="0 0 0" axis="0 1 0" range="-3.1416 1.0472"/>
          <geom type="mesh" rgba="0.792157 0.819608 0.933333 1" mesh="right_shoulder_pitch_link"/>
          <body name="right_shoulder_roll_link" pos="0 -0.057 0">
            <inertial pos="1.294e-05 0.00019306 -0.085944" quat="0.707137 -0.0100122 -0.00276305 0.707" mass="0.610511" diaginertia="0.000919856 0.00078203 0.000292564"/>
            <joint name="right_shoulder_roll_joint" pos="0 0 0" axis="1 0 0" range="-3.1416 0.3491"/>
            <geom type="mesh" rgba="0.792157 0.819608 0.933333 1" mesh="right_shoulder_roll_link"/>
            <body name="right_shoulder_yaw_link" pos="0 0 -0.1315">
              <inertial pos="-2.838e-05 -0.020001 -0.027883" quat="0.971999 0.233099 -0.00848888 0.0284864" mass="0.078836" diaginertia="7.36273e-05 7.1718e-05 1.83447e-05"/>
              <joint name="right_shoulder_yaw_joint" pos="0 0 0" axis="0 0 1" range="-1.5708 1.5708"/>
              <geom type="mesh" rgba="0.79216 0.81961 0.93333 1" mesh="right_shoulder_yaw_link"/>
              <body name="right_elbow_pitch_link" pos="0 0 -0.061">
                <inertial pos="-0.0002278 0.00151852 -0.044548" quat="0.997639 0.0217184 0.00469568 0.0649798" mass="1.01349" diaginertia="0.00257925 0.00249811 0.000284317"/>
                <joint name="right_elbow_pitch_joint" pos="0 0 0" axis="0 1 0" range="-1.8675 0"/>
                <geom type="mesh" rgba="0.792157 0.819608 0.933333 1" mesh="right_elbow_pitch_link"/>
                <body name="right_wrist_yaw_link" pos="0 0 -0.128">
                  <inertial pos="-0.00066742 0.00325051 -0.0343998" quat="0.691332 -0.00526097 0.011877 0.72242" mass="0.124406" diaginertia="0.000136166 0.000132622 2.10627e-05"/>
                  <joint name="right_wrist_yaw_joint" pos="0 0 0" axis="0 0 1" range="-1.5708 1.5708"/>
                  <geom type="mesh" rgba="0.792157 0.819608 0.933333 1" mesh="right_wrist_yaw_link"/>
                </body>
              </body>
            </body>
          </body>
        </body>
      </body>
    </body>
  </worldbody>

  <actuator>
    <motor name="left_leg_pelvic_pitch_joint" joint="left_leg_pelvic_pitch_joint"/>
    <motor name="left_leg_pelvic_roll_joint" joint="left_leg_pelvic_roll_joint"/>
    <motor name="left_leg_pelvic_yaw_joint" joint="left_leg_pelvic_yaw_joint"/>
    <motor name="left_leg_knee_pitch_joint" joint="left_leg_knee_pitch_joint"/>
    <motor name="left_leg_ankle_pitch_joint" joint="left_leg_ankle_pitch_joint"/>
    <motor name="left_leg_ankle_roll_joint" joint="left_leg_ankle_roll_joint"/>
    <motor name="right_leg_pelvic_pitch_joint" joint="right_leg_pelvic_pitch_joint"/>
    <motor name="right_leg_pelvic_roll_joint" joint="right_leg_pelvic_roll_joint"/>
    <motor name="right_leg_pelvic_yaw_joint" joint="right_leg_pelvic_yaw_joint"/>
    <motor name="right_leg_knee_pitch_joint" joint="right_leg_knee_pitch_joint"/>
    <motor name="right_leg_ankle_pitch_joint" joint="right_leg_ankle_pitch_joint"/>
    <motor name="right_leg_ankle_roll_joint" joint="right_leg_ankle_roll_joint"/>
    <motor name="waist_yaw_joint" joint="waist_yaw_joint"/>
    <motor name="head_yaw_joint" joint="head_yaw_joint"/>
    <motor name="head_pitch_joint" joint="head_pitch_joint"/>
    <motor name="left_shoulder_pitch_joint" joint="left_shoulder_pitch_joint"/>
    <motor name="left_shoulder_roll_joint" joint="left_shoulder_roll_joint"/>
    <motor name="left_shoulder_yaw_joint" joint="left_shoulder_yaw_joint"/>
    <motor name="left_elbow_pitch_joint" joint="left_elbow_pitch_joint"/>
    <motor name="left_wrist_yaw_joint" joint="left_wrist_yaw_joint"/>
    <motor name="right_shoulder_pitch_joint" joint="right_shoulder_pitch_joint"/>
    <motor name="right_shoulder_roll_joint" joint="right_shoulder_roll_joint"/>
    <motor name="right_shoulder_yaw_joint" joint="right_shoulder_yaw_joint"/>
    <motor name="right_elbow_pitch_joint" joint="right_elbow_pitch_joint"/>
    <motor name="right_wrist_yaw_joint" joint="right_wrist_yaw_joint"/>
  </actuator>

</mujoco>
